{
 "cells": [
  {
   "cell_type": "code",
   "execution_count": 1,
   "metadata": {},
   "outputs": [],
   "source": [
    "import pandas as pd"
   ]
  },
  {
   "cell_type": "code",
   "execution_count": 9,
   "metadata": {},
   "outputs": [],
   "source": [
    "def split(word):\n",
    "    return [char for char in word]\n",
    "     "
   ]
  },
  {
   "cell_type": "code",
   "execution_count": 12,
   "metadata": {},
   "outputs": [
    {
     "name": "stdout",
     "output_type": "stream",
     "text": [
      "12\n"
     ]
    }
   ],
   "source": [
    "print(len(Lines[0].replace('\\n','')))\n",
    "len_input = len(Lines[0].replace('\\n',''))"
   ]
  },
  {
   "cell_type": "code",
   "execution_count": 27,
   "metadata": {},
   "outputs": [],
   "source": [
    "# Using readlines()\n",
    "file1 = open('input.txt', 'r')\n",
    "Lines = file1.readlines()\n",
    "Lines\n",
    "numbers = []\n",
    "for ele in Lines:\n",
    "    numbers.append(split(ele.replace('\\n','')))\n",
    "\n",
    "#print('numbers: ', numbers)  "
   ]
  },
  {
   "cell_type": "code",
   "execution_count": 38,
   "metadata": {},
   "outputs": [
    {
     "name": "stderr",
     "output_type": "stream",
     "text": [
      "<ipython-input-38-b658972477f4>:2: UserWarning: Pandas doesn't allow columns to be created via a new attribute name - see https://pandas.pydata.org/pandas-docs/stable/indexing.html#attribute-access\n",
      "  df.dtypes = df.astype('int32').dtypes\n"
     ]
    },
    {
     "ename": "AttributeError",
     "evalue": "can't set attribute",
     "output_type": "error",
     "traceback": [
      "\u001b[1;31m---------------------------------------------------------------------------\u001b[0m",
      "\u001b[1;31mAttributeError\u001b[0m                            Traceback (most recent call last)",
      "\u001b[1;32m~\\AppData\\Local\\Programs\\Python\\Python39\\lib\\site-packages\\pandas\\core\\generic.py\u001b[0m in \u001b[0;36m__setattr__\u001b[1;34m(self, name, value)\u001b[0m\n\u001b[0;32m   5490\u001b[0m                 \u001b[1;32melse\u001b[0m\u001b[1;33m:\u001b[0m\u001b[1;33m\u001b[0m\u001b[1;33m\u001b[0m\u001b[0m\n\u001b[1;32m-> 5491\u001b[1;33m                     \u001b[0mobject\u001b[0m\u001b[1;33m.\u001b[0m\u001b[0m__setattr__\u001b[0m\u001b[1;33m(\u001b[0m\u001b[0mself\u001b[0m\u001b[1;33m,\u001b[0m \u001b[0mname\u001b[0m\u001b[1;33m,\u001b[0m \u001b[0mvalue\u001b[0m\u001b[1;33m)\u001b[0m\u001b[1;33m\u001b[0m\u001b[1;33m\u001b[0m\u001b[0m\n\u001b[0m\u001b[0;32m   5492\u001b[0m             \u001b[1;32mexcept\u001b[0m \u001b[1;33m(\u001b[0m\u001b[0mAttributeError\u001b[0m\u001b[1;33m,\u001b[0m \u001b[0mTypeError\u001b[0m\u001b[1;33m)\u001b[0m\u001b[1;33m:\u001b[0m\u001b[1;33m\u001b[0m\u001b[1;33m\u001b[0m\u001b[0m\n",
      "\u001b[1;31mAttributeError\u001b[0m: can't set attribute",
      "\nDuring handling of the above exception, another exception occurred:\n",
      "\u001b[1;31mAttributeError\u001b[0m                            Traceback (most recent call last)",
      "\u001b[1;32m<ipython-input-38-b658972477f4>\u001b[0m in \u001b[0;36m<module>\u001b[1;34m\u001b[0m\n\u001b[0;32m      1\u001b[0m \u001b[0mdf\u001b[0m \u001b[1;33m=\u001b[0m \u001b[0mpd\u001b[0m\u001b[1;33m.\u001b[0m\u001b[0mDataFrame\u001b[0m\u001b[1;33m(\u001b[0m\u001b[0mdata\u001b[0m\u001b[1;33m=\u001b[0m\u001b[0mnumbers\u001b[0m\u001b[1;33m)\u001b[0m\u001b[1;33m\u001b[0m\u001b[1;33m\u001b[0m\u001b[0m\n\u001b[1;32m----> 2\u001b[1;33m \u001b[0mdf\u001b[0m\u001b[1;33m.\u001b[0m\u001b[0mdtypes\u001b[0m \u001b[1;33m=\u001b[0m \u001b[0mdf\u001b[0m\u001b[1;33m.\u001b[0m\u001b[0mastype\u001b[0m\u001b[1;33m(\u001b[0m\u001b[1;34m'int32'\u001b[0m\u001b[1;33m)\u001b[0m\u001b[1;33m.\u001b[0m\u001b[0mdtypes\u001b[0m\u001b[1;33m\u001b[0m\u001b[1;33m\u001b[0m\u001b[0m\n\u001b[0m",
      "\u001b[1;32m~\\AppData\\Local\\Programs\\Python\\Python39\\lib\\site-packages\\pandas\\core\\generic.py\u001b[0m in \u001b[0;36m__setattr__\u001b[1;34m(self, name, value)\u001b[0m\n\u001b[0;32m   5499\u001b[0m                         \u001b[0mstacklevel\u001b[0m\u001b[1;33m=\u001b[0m\u001b[1;36m2\u001b[0m\u001b[1;33m,\u001b[0m\u001b[1;33m\u001b[0m\u001b[1;33m\u001b[0m\u001b[0m\n\u001b[0;32m   5500\u001b[0m                     )\n\u001b[1;32m-> 5501\u001b[1;33m                 \u001b[0mobject\u001b[0m\u001b[1;33m.\u001b[0m\u001b[0m__setattr__\u001b[0m\u001b[1;33m(\u001b[0m\u001b[0mself\u001b[0m\u001b[1;33m,\u001b[0m \u001b[0mname\u001b[0m\u001b[1;33m,\u001b[0m \u001b[0mvalue\u001b[0m\u001b[1;33m)\u001b[0m\u001b[1;33m\u001b[0m\u001b[1;33m\u001b[0m\u001b[0m\n\u001b[0m\u001b[0;32m   5502\u001b[0m \u001b[1;33m\u001b[0m\u001b[0m\n\u001b[0;32m   5503\u001b[0m     \u001b[1;33m@\u001b[0m\u001b[0mfinal\u001b[0m\u001b[1;33m\u001b[0m\u001b[1;33m\u001b[0m\u001b[0m\n",
      "\u001b[1;31mAttributeError\u001b[0m: can't set attribute"
     ]
    }
   ],
   "source": [
    "df = pd.DataFrame(data=numbers)\n",
    "df.dtypes = df.astype('int32').dtypes"
   ]
  },
  {
   "cell_type": "code",
   "execution_count": 37,
   "metadata": {},
   "outputs": [
    {
     "data": {
      "text/plain": [
       "dtype('int32')"
      ]
     },
     "execution_count": 37,
     "metadata": {},
     "output_type": "execute_result"
    }
   ],
   "source": [
    "df[0]"
   ]
  },
  {
   "cell_type": "code",
   "execution_count": null,
   "metadata": {},
   "outputs": [],
   "source": []
  }
 ],
 "metadata": {
  "interpreter": {
   "hash": "f21f743cc6c41fc33e520d2d26f99532d48e5b1bbd397170bfb0442f3e446286"
  },
  "kernelspec": {
   "display_name": "Python 3.9.1 64-bit",
   "name": "python3"
  },
  "language_info": {
   "codemirror_mode": {
    "name": "ipython",
    "version": 3
   },
   "file_extension": ".py",
   "mimetype": "text/x-python",
   "name": "python",
   "nbconvert_exporter": "python",
   "pygments_lexer": "ipython3",
   "version": "3.9.1"
  },
  "orig_nbformat": 4
 },
 "nbformat": 4,
 "nbformat_minor": 2
}
